cloning mvretail and simplesamlphp
Cloning into 'MVRetail'...
Updating files: 100% (28319/28319), done.
Cloning into 'SimpleSAMLphp'...
installing loguru dependency
mcp exported
Traceback (most recent call last):
  File "/home/jenkins/.local/lib/python3.10/site-packages/urllib3/connection.py", line 174, in _new_conn
    conn = connection.create_connection(
  File "/home/jenkins/.local/lib/python3.10/site-packages/urllib3/util/connection.py", line 95, in create_connection
    raise err
  File "/home/jenkins/.local/lib/python3.10/site-packages/urllib3/util/connection.py", line 85, in create_connection
    sock.connect(sa)
TimeoutError: [Errno 110] Connection timed out

During handling of the above exception, another exception occurred:

Traceback (most recent call last):
  File "/home/jenkins/.local/lib/python3.10/site-packages/urllib3/connectionpool.py", line 716, in urlopen
    httplib_response = self._make_request(
  File "/home/jenkins/.local/lib/python3.10/site-packages/urllib3/connectionpool.py", line 404, in _make_request
    self._validate_conn(conn)
  File "/home/jenkins/.local/lib/python3.10/site-packages/urllib3/connectionpool.py", line 1061, in _validate_conn
    conn.connect()
  File "/home/jenkins/.local/lib/python3.10/site-packages/urllib3/connection.py", line 363, in connect
    self.sock = conn = self._new_conn()
  File "/home/jenkins/.local/lib/python3.10/site-packages/urllib3/connection.py", line 179, in _new_conn
    raise ConnectTimeoutError(
urllib3.exceptions.ConnectTimeoutError: (<urllib3.connection.HTTPSConnection object at 0x7f0e833829e0>, 'Connection to devw-bastion-internal.mvretail.com timed out. (connect timeout=None)')

During handling of the above exception, another exception occurred:

Traceback (most recent call last):
  File "/home/jenkins/.local/lib/python3.10/site-packages/requests/adapters.py", line 486, in send
    resp = conn.urlopen(
  File "/home/jenkins/.local/lib/python3.10/site-packages/urllib3/connectionpool.py", line 802, in urlopen
    retries = retries.increment(
  File "/home/jenkins/.local/lib/python3.10/site-packages/urllib3/util/retry.py", line 594, in increment
    raise MaxRetryError(_pool, url, error or ResponseError(cause))
urllib3.exceptions.MaxRetryError: HTTPSConnectionPool(host='devw-bastion-internal.mvretail.com', port=443): Max retries exceeded with url: /buildArtifact (Caused by ConnectTimeoutError(<urllib3.connection.HTTPSConnection object at 0x7f0e833829e0>, 'Connection to devw-bastion-internal.mvretail.com timed out. (connect timeout=None)'))

During handling of the above exception, another exception occurred:

Traceback (most recent call last):
  File "/home/jenkins/project/get_ui_artifacts.py", line 34, in <module>
    response = requests.post(build_url, headers=headers, json=payload)
  File "/home/jenkins/.local/lib/python3.10/site-packages/requests/api.py", line 115, in post
    return request("post", url, data=data, json=json, **kwargs)
  File "/home/jenkins/.local/lib/python3.10/site-packages/requests/api.py", line 59, in request
    return session.request(method=method, url=url, **kwargs)
  File "/home/jenkins/.local/lib/python3.10/site-packages/requests/sessions.py", line 589, in request
    resp = self.send(prep, **send_kwargs)
  File "/home/jenkins/.local/lib/python3.10/site-packages/requests/sessions.py", line 703, in send
    r = adapter.send(request, **kwargs)
  File "/home/jenkins/.local/lib/python3.10/site-packages/requests/adapters.py", line 507, in send
    raise ConnectTimeout(e, request=request)
requests.exceptions.ConnectTimeout: HTTPSConnectionPool(host='devw-bastion-internal.mvretail.com', port=443): Max retries exceeded with url: /buildArtifact (Caused by ConnectTimeoutError(<urllib3.connection.HTTPSConnection object at 0x7f0e833829e0>, 'Connection to devw-bastion-internal.mvretail.com timed out. (connect timeout=None)'))

Exited with code exit status 1
